Workbook

Sheet Planilha1
A1: Código de Barras | B1: Descrição do Produto | D1: 2 | E1: 3 | F1: 4 | G1: 5 | H1: 6 | I1: 7 | J1: 8 | K1: 9 | L1: 10 | M1: Classificação
A2: 7897780225708 | B2: AGUA BORICADA 3% 100ML | C2: 2.91 | D2: =VLOOKUP($A2,Planilha2!$A$2:$Q$2208,D$1,FALSE) | E2: =VLOOKUP($A2,Planilha2!$A$2:$Q$2208,E$1,FALSE) | F2: =VLOOKUP($A2,Planilha2!$A$2:$Q$2208,F$1,FALSE) | G2: =VLOOKUP($A2,Planilha2!$A$2:$Q$2208,G$1,FALSE) | H2: =VLOOKUP($A2,Planilha2!$A$2:$Q$2208,H$1,FALSE) | I2: =VLOOKUP($A2,Planilha2!$A$2:$Q$2208,I$1,FALSE) | J2: =VLOOKUP($A2,Planilha2!$A$2:$Q$2208,J$1,FALSE) | K2: =VLOOKUP($A2,Planilha2!$A$2:$Q$2208,K$1,FALSE) | L2: =VLOOKUP($A2,Planilha2!$A$2:$Q$2208,L$1,FALSE) | M2: PERFUMARIA > HIGIENE PESSOAL
A3: 7896902210561 | B3: AGUA OXIG 20 VL 90 ML FARMAX | C3: 3.0333333 | D3: =VLOOKUP($A3,Planilha2!A3:Q2209,$D$1,FALSE) | E3: =VLOOKUP($A3,Planilha2!$A$2:$Q$2208,E$1,FALSE) | F3: =VLOOKUP($A3,Planilha2!$A$2:$Q$2208,F$1,FALSE) | G3: =VLOOKUP($A3,Planilha2!$A$2:$Q$2208,G$1,FALSE) | H3: =VLOOKUP($A3,Planilha2!$A$2:$Q$2208,H$1,FALSE) | I3: =VLOOKUP($A3,Planilha2!$A$2:$Q$2208,I$1,FALSE) | J3: =VLOOKUP($A3,Planilha2!$A$2:$Q$2208,J$1,FALSE) | K3: =VLOOKUP($A3,Planilha2!$A$2:$Q$2208,K$1,FALSE) | L3: =VLOOKUP($A3,Planilha2!$A$2:$Q$2208,L$1,FALSE) | M3: PERFUMARIA > TINTURAS
A4: 7896902205758 | B4: PEDRA HUME PO 20 GR FARMAX | C4: 4.87 | D4: =VLOOKUP($A4,Planilha2!A4:Q2210,$D$1,FALSE) | E4: =VLOOKUP($A4,Planilha2!$A$2:$Q$2208,E$1,FALSE) | F4: =VLOOKUP($A4,Planilha2!$A$2:$Q$2208,F$1,FALSE) | G4: =VLOOKUP($A4,Planilha2!$A$2:$Q$2208,G$1,FALSE) | H4: =VLOOKUP($A4,Planilha2!$A$2:$Q$2208,H$1,FALSE) | I4: =VLOOKUP($A4,Planilha2!$A$2:$Q$2208,I$1,FALSE) | J4: =VLOOKUP($A4,Planilha2!$A$2:$Q$2208,J$1,FALSE) | K4: =VLOOKUP($A4,Planilha2!$A$2:$Q$2208,K$1,FALSE) | L4: =VLOOKUP($A4,Planilha2!$A$2:$Q$2208,L$1,FALSE) | M4: PERFUMARIA > HIGIENE PESSOAL
A5: 7896512900043 | B5: GRANADO SAB ENXOFRE 90 GR | C5: 10.65 | D5: =VLOOKUP($A5,Planilha2!A5:Q2211,$D$1,FALSE) | E5: =VLOOKUP($A5,Planilha2!$A$2:$Q$2208,E$1,FALSE) | F5: =VLOOKUP($A5,Planilha2!$A$2:$Q$2208,F$1,FALSE) | G5: =VLOOKUP($A5,Planilha2!$A$2:$Q$2208,G$1,FALSE) | H5: =VLOOKUP($A5,Planilha2!$A$2:$Q$2208,H$1,FALSE) | I5: =VLOOKUP($A5,Planilha2!$A$2:$Q$2208,I$1,FALSE) | J5: =VLOOKUP($A5,Planilha2!$A$2:$Q$2208,J$1,FALSE) | K5: =VLOOKUP($A5,Planilha2!$A$2:$Q$2208,K$1,FALSE) | L5: =VLOOKUP($A5,Planilha2!$A$2:$Q$2208,L$1,FALSE) | M5: PERFUMARIA > DERMOCOSMETICOS
A6: 7897947622043 | B6: JOAO E MARIA SABONETE BARRA 75G LAVANDA | C6: 3.12 | D6: =VLOOKUP($A6,Planilha2!A6:Q2212,$D$1,FALSE) | E6: =VLOOKUP($A6,Planilha2!$A$2:$Q$2208,E$1,FALSE) | F6: =VLOOKUP($A6,Planilha2!$A$2:$Q$2208,F$1,FALSE) | G6: =VLOOKUP($A6,Planilha2!$A$2:$Q$2208,G$1,FALSE) | H6: =VLOOKUP($A6,Planilha2!$A$2:$Q$2208,H$1,FALSE) | I6: =VLOOKUP($A6,Planilha2!$A$2:$Q$2208,I$1,FALSE) | J6: =VLOOKUP($A6,Planilha2!$A$2:$Q$2208,J$1,FALSE) | K6: =VLOOKUP($A6,Planilha2!$A$2:$Q$2208,K$1,FALSE) | L6: =VLOOKUP($A6,Planilha2!$A$2:$Q$2208,L$1,FALSE) | M6: PERFUMARIA > LINHA INFANTIL
A7: 7897947620193 | B7: JOAO E MARIA SAB BARRA BABY GLIC 75G | C7: 3.74 | D7: =VLOOKUP($A7,Planilha2!A7:Q2213,$D$1,FALSE) | E7: =VLOOKUP($A7,Planilha2!$A$2:$Q$2208,E$1,FALSE) | F7: =VLOOKUP($A7,Planilha2!$A$2:$Q$2208,F$1,FALSE) | G7: =VLOOKUP($A7,Planilha2!$A$2:$Q$2208,G$1,FALSE) | H7: =VLOOKUP($A7,Planilha2!$A$2:$Q$2208,H$1,FALSE) | I7: =VLOOKUP($A7,Planilha2!$A$2:$Q$2208,I$1,FALSE) | J7: =VLOOKUP($A7,Planilha2!$A$2:$Q$2208,J$1,FALSE) | K7: =VLOOKUP($A7,Planilha2!$A$2:$Q$2208,K$1,FALSE) | L7: =VLOOKUP($A7,Planilha2!$A$2:$Q$2208,L$1,FALSE) | M7: PERFUMARIA > LINHA INFANTIL
A8: 7897947620186 | B8: JOAO E MARIA SAB BARRA BABY CREM 75G | C8: 3.74 | D8: =VLOOKUP($A8,Planilha2!A8:Q2214,$D$1,FALSE) | E8: =VLOOKUP($A8,Planilha2!$A$2:$Q$2208,E$1,FALSE) | F8: =VLOOKUP($A8,Planilha2!$A$2:$Q$2208,F$1,FALSE) | G8: =VLOOKUP($A8,Planilha2!$A$2:$Q$2208,G$1,FALSE) | H8: =VLOOKUP($A8,Planilha2!$A$2:$Q$2208,H$1,FALSE) | I8: =VLOOKUP($A8,Planilha2!$A$2:$Q$2208,I$1,FALSE) | J8: =VLOOKUP($A8,Planilha2!$A$2:$Q$2208,J$1,FALSE) | K8: =VLOOKUP($A8,Planilha2!$A$2:$Q$2208,K$1,FALSE) | L8: =VLOOKUP($A8,Planilha2!$A$2:$Q$2208,L$1,FALSE) | M8: PERFUMARIA > LINHA INFANTIL
A9: 7897947612334 | B9: BEPANTRIZ DERMA SOL SPRAY 50 ML | C9: 6.85 | D9: =VLOOKUP($A9,Planilha2!A9:Q2215,$D$1,FALSE) | E9: =VLOOKUP($A9,Planilha2!$A$2:$Q$2208,E$1,FALSE) | F9: =VLOOKUP($A9,Planilha2!$A$2:$Q$2208,F$1,FALSE) | G9: =VLOOKUP($A9,Planilha2!$A$2:$Q$2208,G$1,FALSE) | H9: =VLOOKUP($A9,Planilha2!$A$2:$Q$2208,H$1,FALSE) | I9: =VLOOKUP($A9,Planilha2!$A$2:$Q$2208,I$1,FALSE) | J9: =VLOOKUP($A9,Planilha2!$A$2:$Q$2208,J$1,FALSE) | K9: =VLOOKUP($A9,Planilha2!$A$2:$Q$2208,K$1,FALSE) | L9: =VLOOKUP($A9,Planilha2!$A$2:$Q$2208,L$1,FALSE) | M9: PERFUMARIA > DERMOCOSMETICOS
A10: 7897947617032 | B10: ACNEZIL SAB PELE OLEOSA 70 GR | C10: 7.01 | D10: =VLOOKUP($A10,Planilha2!A10:Q2216,$D$1,FALSE) | E10: =VLOOKUP($A10,Planilha2!$A$2:$Q$2208,E$1,FALSE) | F10: =VLOOKUP($A10,Planilha2!$A$2:$Q$2208,F$1,FALSE) | G10: =VLOOKUP($A10,Planilha2!$A$2:$Q$2208,G$1,FALSE) | H10: =VLOOKUP($A10,Planilha2!$A$2:$Q$2208,H$1,FALSE) | I10: =VLOOKUP($A10,Planilha2!$A$2:$Q$2208,I$1,FALSE) | J10: =VLOOKUP($A10,Planilha2!$A$2:$Q$2208,J$1,FALSE) | K10: =VLOOKUP($A10,Planilha2!$A$2:$Q$2208,K$1,FALSE) | L10: =VLOOKUP($A10,Planilha2!$A$2:$Q$2208,L$1,FALSE) | M10: PERFUMARIA > DERMOCOSMETICOS
A11: 7897947617025 | B11: ACNEZIL SAB PELE ACNEICA 70 GR | C11: 7.01 | D11: =VLOOKUP($A11,Planilha2!A11:Q2217,$D$1,FALSE) | E11: =VLOOKUP($A11,Planilha2!$A$2:$Q$2208,E$1,FALSE) | F11: =VLOOKUP($A11,Planilha2!$A$2:$Q$2208,F$1,FALSE) | G11: =VLOOKUP($A11,Planilha2!$A$2:$Q$2208,G$1,FALSE) | H11: =VLOOKUP($A11,Planilha2!$A$2:$Q$2208,H$1,FALSE) | I11: =VLOOKUP($A11,Planilha2!$A$2:$Q$2208,I$1,FALSE) | J11: =VLOOKUP($A11,Planilha2!$A$2:$Q$2208,J$1,FALSE) | K11: =VLOOKUP($A11,Planilha2!$A$2:$Q$2208,K$1,FALSE) | L11: =VLOOKUP($A11,Planilha2!$A$2:$Q$2208,L$1,FALSE) | M11: PERFUMARIA > DERMOCOSMETICOS
A12: 7896523207834 | B12: K-MED GEL BG 25 G | C12: 7.88 | D12: =VLOOKUP($A12,Planilha2!A12:Q2218,$D$1,FALSE) | E12: =VLOOKUP($A12,Planilha2!$A$2:$Q$2208,E$1,FALSE) | F12: =VLOOKUP($A12,Planilha2!$A$2:$Q$2208,F$1,FALSE) | G12: =VLOOKUP($A12,Planilha2!$A$2:$Q$2208,G$1,FALSE) | H12: =VLOOKUP($A12,Planilha2!$A$2:$Q$2208,H$1,FALSE) | I12: =VLOOKUP($A12,Planilha2!$A$2:$Q$2208,I$1,FALSE) | J12: =VLOOKUP($A12,Planilha2!$A$2:$Q$2208,J$1,FALSE) | K12: =VLOOKUP($A12,Planilha2!$A$2:$Q$2208,K$1,FALSE) | L12: =VLOOKUP($A12,Planilha2!$A$2:$Q$2208,L$1,FALSE) | M12: PERFUMARIA > HIGIENE PESSOAL
A13: 7897947612273 | B13: BEPANTRIZ DERMA CRM 20 GR | C13: 9.52 | D13: =VLOOKUP($A13,Planilha2!A13:Q2219,$D$1,FALSE) | E13: =VLOOKUP($A13,Planilha2!$A$2:$Q$2208,E$1,FALSE) | F13: =VLOOKUP($A13,Planilha2!$A$2:$Q$2208,F$1,FALSE) | G13: =VLOOKUP($A13,Planilha2!$A$2:$Q$2208,G$1,FALSE) | H13: =VLOOKUP($A13,Planilha2!$A$2:$Q$2208,H$1,FALSE) | I13: =VLOOKUP($A13,Planilha2!$A$2:$Q$2208,I$1,FALSE) | J13: =VLOOKUP($A13,Planilha2!$A$2:$Q$2208,J$1,FALSE) | K13: =VLOOKUP($A13,Planilha2!$A$2:$Q$2208,K$1,FALSE) | L13: =VLOOKUP($A13,Planilha2!$A$2:$Q$2208,L$1,FALSE) | M13: PERFUMARIA > DERMOCOSMETICOS
A14: 7897947615250 | B14: BEPANTRIZ TATTOO CRM 20 GR | C14: 9.52 | D14: =VLOOKUP($A14,Planilha2!A14:Q2220,$D$1,FALSE) | E14: =VLOOKUP($A14,Planilha2!$A$2:$Q$2208,E$1,FALSE) | F14: =VLOOKUP($A14,Planilha2!$A$2:$Q$2208,F$1,FALSE) | G14: =VLOOKUP($A14,Planilha2!$A$2:$Q$2208,G$1,FALSE) | H14: =VLOOKUP($A14,Planilha2!$A$2:$Q$2208,H$1,FALSE) | I14: =VLOOKUP($A14,Planilha2!$A$2:$Q$2208,I$1,FALSE) | J14: =VLOOKUP($A14,Planilha2!$A$2:$Q$2208,J$1,FALSE) | K14: =VLOOKUP($A14,Planilha2!$A$2:$Q$2208,K$1,FALSE) | L14: =VLOOKUP($A14,Planilha2!$A$2:$Q$2208,L$1,FALSE) | M14: PERFUMARIA > DERMOCOSMETICOS
... A1069: 7891010254995 | B1069: NEUTROGENA NORMEGIAN HIDRAT CORP INTENS S/ FRAGRANCIA 400 | C1069: 82.575 | D1069: =VLOOKUP($A1069,Planilha2!A1069:Q3275,$D$1,FALSE) | E1069: =VLOOKUP($A1069,Planilha2!$A$2:$Q$2208,E$1,FALSE) | F1069: =VLOOKUP($A1069,Planilha2!$A$2:$Q$2208,F$1,FALSE) | G1069: =VLOOKUP($A1069,Planilha2!$A$2:$Q$2208,G$1,FALSE) | H1069: =VLOOKUP($A1069,Planilha2!$A$2:$Q$2208,H$1,FALSE) | I1069: =VLOOKUP($A1069,Planilha2!$A$2:$Q$2208,I$1,FALSE) | J1069: =VLOOKUP($A1069,Planilha2!$A$2:$Q$2208,J$1,FALSE) | K1069: =VLOOKUP($A1069,Planilha2!$A$2:$Q$2208,K$1,FALSE) | L1069: =VLOOKUP($A1069,Planilha2!$A$2:$Q$2208,L$1,FALSE) | M1069: PERFUMARIA > COLONIAS & DESODORANTES

Sheet Planilha2
A1: EAN | B1: Droga Raia | C1: Nissei | D1: São João | E1: São Paulo | F1: Panvel | G1: Pague Menos | H1: Preço Popular | I1: Drogaria São Paulo
A2: 7898074617803 | B2: Spidufen Ibuprofeno 600mg + Arginina 555mg Sabor Damasco 10 envelopes de 3g | C2: Spidufen 1155mg ( Ibuprofeno 600mg + Arginina 555mg) Granulado Sabor Damasco para Solução Oral 10 envelopes 3g | D2: Spidufen 600/555 1155mg 10 Sachês Sabor Damasco Zambon | E2: Spidufen Ibuprofeno 600mg + Arginina 555mg Sabor Damasco 10 Envelopes De 3g | F2: SPIDUFEN 1155MG / 600MG C/10 SACHÊS DAMASCO | G2: Spidufen 600mg Sabor Damasco Granulado para Solução Oral 10 Envelopes | H2: Spidufen Com 10 Envelopes 600mg Damasco | I2: Spidufen Ibuprofeno Arginina Damasco 1155mg 10 Envelopes
A3: 7898074618183 | B3: Seki Fendizoato de Cloperastina 3,54mg/ml Sabor Coco Xarope 120ml | C3: Seki 3,54 mg/mL Xarope Sabor Coco 120ml | D3: Xarope Seki Sabor Coco 120ml | E3: Seki Fendizoato De Cloperastina 3,54mg/Ml Sabor Coco Xarope 120ml | F3: SEKI 3,54 MG/ML XAROPE SABOR COCO 120ML | G3: Seki 3,54mg/ml Sabor Coco Xarope 120ml | H3: Seki 3,54 Mg/ml Xarope Sabor Coco 120ml Zambon | I3: Antitussígeno Seki 3,54mg/ml sabor Coco 120ml Xarope
A4: 7891182016247 | B4: Tintura Koleston Creme Cor 30 Castanho Escuro | C4: Tintura Koleston 30 Castanho Escuro | E4: Tintura Koleston Creme Cor 30 Castanho Escuro | F4: TINTURA KOLESTON 30 CASTANHO ESCURO | G4: Tintura Koleston castanho Escuro 30 | H4: Tintura Koleston 30 Castanho Escuro | I4: Tinta de Cabelo Wella Koleston 30 Castanho Escuro
A5: 7891182016254 | B5: Tinta de Cabelo Permanente Koleston Creme - Castanho Médio | C5: Tintura Koleston 40 Castanho Médio | F5: TINTURA KOLESTON 40 CASTANHO MÉDIO | G5: Tintura Koleston castanho Médio Kit 40 | H5: Tintura Koleston 40 Castanho Medio | I5: Tinta de Cabelo Wella Koleston 40 Castanho Médio
A6: 7891182016223 | B6: Tintura Creme Koleston Nº20 Preto 1 Unidade | C6: Tintura Koleston 20 Preto | F6: TINTURA KOLESTON 20 PRETO | G6: Tintura Koleston preto 20 | H6: Tintura Koleston 20 Preto | I6: Tinta de Cabelo Koleston 20 Preto
A7: 7898049793310 | B7: Ivermectina 6mg 4 comprimidos Vitamedic Genérico | C7: Ivermectina Vitapan 6mg 4 Comprimidos | D7: Ivermectina 6mg 4 Comprimidos Genérico Vitamedic | E7: Ivermectina 6mg Com 04 Comprimidos Vitamedic Genérico | G7: Ivermectina 6mg 4 Comprimidos Genérico Vitamedic | H7: Ivermectina Vitamedic 6mg Com 4 Comprimidos | I7: Ivermectina 6mg Genérico Vitamedic 4 Comprimidos
A8: 7898049790586 | B8: Vertizan Dicloridrato de Flunarizina 10mg 50 comprimidos | C8: Vertizan 10MG 50 Comprimidos | D8: Vertizan 10mg 50 Comprimidos | E8: Vertizan Dicloridrato De Flunarizina 10mg 50 Comprimidos | G8: Vertizan 10mg 50 Comprimidos | H8: Vertizan Dicloridrato De Flunarizina 10mg 50 Comprimidos Vitamedic
A9: 7898049796830 | B9: Fosfato Sódico de Prednisolona 3mg/ml Solução Oral 60ml Vitamedic Genérico | C9: Fosfato Sódico de Prednisolona Vitamedic 60ml | D9: Fosfato Sódico de Prednisolona 3mg/ml 60ml Genérico Vitamedic | E9: Fosfato Sódico De Prednisolona 3mg/Ml Solução Oral 60ml Vitamedic Genérico | F9: FOSFATO SÓDICO DE PREDNISOLONA 3MG/ML 60ML SOLUÇÃO ORAL VITAMEDIC GENÉRICO | G9: Fosfato Sódico de Prednisolona 3mg/ml Solução Oral 60ml Genérico Vitamedic | H9: Prednisolona Vitamedic 60ml Solucao Oral 3mg/ml Generico | I9: Fosfato Sódico de Prednisolona 3mg/ml Genérico Vitamedic 60ml
A10: 7898049796168 | B10: Fluconazol 150mg 2 cápsulas Vitamedic Genérico | F10: FLUCONAZOL 150MG 2 CAPSULAS VITAMEDIC GENERICO | H10: Fluconazol Vitamedic Com 2 Capsulas 150mg Generico | I10: Fluconazol 150mg Genérico Vitamedic 2 Cápsulas
A11: 7898049798681 | B11: Cloridrato de Ciclobenzaprina 5mg - 15 comprimidos Vitamedic Genérico
A12: 7898049796519 | B12: Algy-Flanderil Ibuprofeno 600mg 20 comprimidos | D12: Ibuprofeno 600mg 20 Comprimidos Algy-Fland Vitamedic | E12: Algy-Flanderil Ibuprofeno 600mg 20 Comprimidos | G12: Algy-Flanderil 600mg 20 Comprimidos | H12: Algy Flanderil 600mg Com 20 Comprimidos
A13: 7898700412758 | E13: Algy-Flanderil 600mg C/30 Comp
A14: 7898605844975 | D14: Nutravitta Magnésio Dimalato 60 Cápsulas Sorocaps
A15: 7891037010048 | B15: Creme para Pentear Seda Liso Perfeito com 300ml | C15: Creme para Pentear Seda Liso Perfeito 300ml | D15: Creme para Pentear Seda Lissage Liso Perfeito 300ml | E15: Creme Para Pentear Seda Liso Perfeito Com 300ml | F15: CREME PARA PENTEAR SEDA LISO PERFEITO 300ML | G15: Creme de Pentear Seda Liso Perfeito 300ml | H15: Creme Para Pentear Seda Liso Perfeito 300ml | I15: Creme para Pentear Seda Liso Perfeito Feminino 300ml
A16: 7891150091436 | B16: Creme para Pentear Seda Força e Crescimento Prebióticos + Biotina 300ml | C16: Creme para Pentear Seda Prebióticos+Biotina Força e Crescimento 300ml | D16: Creme para Pentear Seda Força e Crescimento 300ml | E16: Creme Para Pentear Seda Força E Crescimento Prebióticos + Biotina 300ml | G16: Creme de Pentear Seda Força & Crescimento Prebióticos + Biotina 300ml | H16: Creme Para Pentear Seda 300ml Prebioticos+biotina | I16: Creme Para Pentear Seda Prebióticos + Biotina 300ml
A17: 7791293022581 | B17: Desodorante Antitranspirante Aerosol Rexona Men Xtracool 72h 150ml | C17: Antitranspirante Rexona Men Xtracool 150 ml | E17: Desodorante Antitranspirante Aerosol Rexona Men Xtracool 72h 150ml | F17: DESODORANTE ANTITRANSPIRANTE AEROSOL MASCULINO REXONA EXTRACOOL 72 HORAS 150ML | G17: Desodorante Antitranspirante Rexona Men Xtracool 72h Aerossol 150ml | H17: Antitranspirante Aerossol Rexona Men Xtracool 150ml | I17: Desodorante Antitranspirante Aerosol Masculino Rexona Extracool 72 horas 150ml
A18: 7791293022567 | B18: Desodorante Antitranspirante Aerosol Rexona Men V8 72h 150ml | C18: Desodorante Antitranspirante Aerosol Masculino Rexona V8 72 horas 150ml | E18: Desodorante Antitranspirante Aerosol Rexona Men V8 72h 150ml | F18: DESODORANTE ANTITRANSPIRANTE AEROSOL MASCULINO REXONA V8 72 HORAS 150ML | G18: Desodorante Antitranspirante Rexona Men V8 72h Aerossol 150ml | H18: Antitranspirante Aerossol Rexona Men V8 Dry 150ml | I18: Desodorante Antitranspirante Aerosol Masculino Rexona V8 72 horas 150ml
A19: 7891150055872 | B19: Desodorante Antitranspirante Aerosol Rexona Men Sem Perfume 72h 150ml | C19: Desodorante Antitranspirante Aerosol Masculino Rexona Sem Perfume 72Horas 150ml | D19: Desodorante Antitranspirante Aerossol Rexona Men Sem Perfume Hipoalergênico 150ml | E19: Desodorante Antitranspirante Aerosol Rexona Men Sem Perfume 72h 150ml | F19: DESODORANTE AEROSOL REXONA MEN SEM PERFUME 150ML | G19: Desodorante Antitranspirante Rexona Men Sem Perfume 72h Aerossol 150ml | H19: Antitranspirante Aerossol Rexona Men Sem Perfume 150ml | I19: Desodorante Antitranspirante Aerosol Masculino Rexona Sem Perfume 72 horas 150ml
A20: 7891150064737 | B20: Desodorante Antitranspirante Aerosol Rexona Frutas Vermelhas Feminino 72h 150ml | C20: Desodorante Antitranspirante Aerosol Rexona Frutas Vermelhas 72 horas 150ml | D20: Desodorante Antitranspirante Aerossol Rexona Frutas Vermelhas 150ml | E20: Desodorante Antitranspirante Aerosol Rexona Frutas Vermelhas Feminino 72h 150ml | F20: DESODORANTE ANTITRANSPIRANTE AEROSOL REXONA FEMININO FRUTAS VERMELHAS 150ML | G20: Desodorante Antitranspirante Rexona MotionSense Frutas Vermelhas 48h Aerossol 150ml | H20: Antitranspirante Aerossol Rexona Frutas Vermelhas Fresh 150ml | I20: Desodorante Feminino Rexona Frutas Vermelhas Aerosol 150ml
A21: 7791293032368 | B21: Desodorante Antitranspirante Aerosol Rexona Sem Perfume Feminino 72h 150ml | C21: Antitranspirante Aerosol Rexona Sem Perfume 150ml | E21: Desodorante Antitranspirante Aerosol Rexona Sem Perfume Feminino 72h 150ml | F21: DESODORANTE ANTITRANSPIRANTE AEROSOL FEMININO REXONA SEM PERFUME 72 HORAS 150ML | G21: Desodorante Antitranspirante Rexona Sem Perfume 72h Aerossol 150ml | H21: Antitranspirante Aerossol Rexona Sem Perfume 150ml | I21: Desodorante Antitranspirante Aerosol Feminino Rexona Sem Perfume 72 horas 150ml
A22: 7791293032467 | B22: Desodorante Antitranspirante Rexona Cotton Dry Aerosol 150ml | C22: Desodorante Rexona Feminino Cotton Dry 150ml | D22: Rexona Antitranspirante Cotton Dry Aerosol 150ml | E22: Desodorante Antitranspirante Aerosol Rexona Cotton Dry Feminino 72h 150ml | F22: DESODORANTE ANTITRANSPIRANTE AEROSOL REXONA FEMININO COTTON DRY 150ML | G22: Desodorante Antitranspirante Rexona Cotton Dry 72h Aerossol 150ml | H22: Antitranspirante Aerossol Rexona Cotton Dry 150ml | I22: Desodorante Antitranspirante Aerosol Feminino Rexona Cotton Dry 72 horas 150ml
A23: 7791293049564
A24: 7791293051550 | B24: Desodorante Corporal Aerossol Rexona All Body Deo Fresh Citrus 150ml | C24: All Body Deo Rexona Fresh Citrus Aerosol 150ml | D24: Desodorante Antitranspirante Aerossol Rexona All Body Fresh Citrus 150ml | F24: DESODORANTE CORPORAL AEROSOL REXONA ALL OVER BODY FRESH CITRUS 150ML | G24: Desodorante Corporal Rexona All Body Deo Fresh Citrus Aerossol 150ml | H24: Desodorante Rexona Feminino All Body Deo Fresh Citrus 150ml | I24: Desodorante Aerossol Rexona All Body Deo Fresh Citrus 150ml Spray
A25: 7791293022598 | B25: Desodorante Antitranspirante Aerosol Rexona Men Active Dry Masculino 72h 150ml | C25: Antitranspirante Rexona Men Active Dry 150 ml | D25: Desodorante Antitranspirante Aerossol Rexona Men Active 150ml | E25: Desodorante Antitranspirante Aerosol Rexona Men Active Dry Masculino 72h 150ml | F25: DESODORANTE ANTITRANSPIRANTE AEROSOL MASCULINO REXONA ACTIVE DRY 72 HORAS 150ML | G25: Desodorante Antitranspirante Rexona Men Active Dry 72h Aerossol 150ml | H25: Antitranspirante Aerossol Rexona Men Active Dry 150ml | I25: Desodorante Antitranspirante Aerosol Masculino Rexona Active Dry 72 horas 150ml
A26: 7791293032443 | B26: Desodorante Antitranspirante Aerosol Rexona Active Emotion Feminino 48h 150ml | C26: Desodorante Rexona Feminino Active Emotion 150ml | E26: Desodorante Antitranspirante Aerosol Rexona Active Emotion Feminino 72h 150ml | F26: DESODORANTE AEROSOL REXONA ACTIVE EMOTION DRY 150ML | G26: Desodorante Antitranspirante Rexona Active Emotion 72h Aerossol 150ml | H26: Antitranspirante Aerossol Rexona Active Emotion Dry 150ml | I26: Desodorante Antitranspirante Aerosol Feminino Rexona Active Emotion 72 horas 150ml
A27: 7891150100510 | B27: Desodorante Antitranspirante Aerossol Rexona Clinical Invisible Masculino 96h 150ml | C27: Desodorante Rexona Aerossol 96h Clinical Men Invisible 150ml | D27: Desodorante Antitranspirante Aerossol Rexona Clinical Invisible Men 150ml | F27: DESODORANTE AEROSOL REXONA CLINICAL MASCULINO INVISIBLE 150ML | G27: Desodorante Rexona Clinical Invisible Men Aerosol 150ml | H27: Desodorante Rexona Clinical Men Aerosol Invisible 150ml | I27: Desodorante Antitranspirante Rexona Clinical Men Invisible 150ml Aerossol
A28: 7891150089983 | B28: Desodorante Antitranspirante Aerosol Rexona Clinical Intense Fresh Masculino 96h 150ml | C28: Desodorante Rexona Clinical Intense Fresh 91 g | D28: Desodorante Antitranspirante Aerossol Rexona Clinical Intense Fresh 96h 150ml | E28: Desodorante Antitranspirante Aerosol Rexona Clinical Intense Fresh Masculino 96h 150ml | F28: DESODORANTE AEROSSOL REXONA CLINICAL INTENSE FRESH 96H 150ML | G28: Desodorante Antitranspirante Rexona Clinical Intense Fresh 96h Aerossol 150ml | H28: Desodorante Rexona Masculino Clinical 150ml Aerosol Intense Fresh | I28: Desodorante Aerossol Rexona Clinical Intense Fresh 150ml
A29: 7506306214989 | B29: Desodorante Antitranspirante Aerosol Rexona Clinical Classic Feminino 96h 150ml | C29: Antitranspirante Aerosol Rexona Clinical Classic 150 ml | D29: Desodorante Antitranspirante Aerossol Rexona Clinical Classic 150ml | E29: Desodorante Antitranspirante Aerosol Rexona Clinical Classic Feminino 96h 150ml | F29: DESODORANTE ANTITRANSPIRANTE AEROSOL REXONA CLINICAL CLASSIC 96H 150ML | G29: Desodorante Antitranspirante Rexona Clinical Classic 96h Aerossol 150ml | H29: Desodorante Feminino Rexona Clinical Classic 150ml | I29: Desodorante Feminino Rexona Clinical Classic Aerosol 150ml
A30: 0000042355465 | B30: Creme Hidratante Nivea Men 4 em 1 com 30g | C30: Nivea Men Creme 4 em 1 30g | G30: Hidratante Nivea Men 4 em 1 Creme 30g | H30: Creme Nivea Men 4 Em 1 30g | I30: Creme Hidratante Nivea Men 4 em 1 30g
A31: 7509546702988 | B31: Kit Viagem Colgate Total Prevenção Ativa Enxaguante Bucal Sem Álcool 60ml + Pasta de Dente 30g + Escova de Dente | C31: Kit Estojo + Creme Dental Anticárie Original Mint 30g + Enxaguante Bucal Antibacteriano Clean Mint 60ml Prevenção Ativa + Escova Dental Macia Cabeça Normal Colgate Total | D31: Kit Viagem Colgate Creme Dental Total Mint + Escova Dental + Enxaguante Bucal | F31: KIT VIAGEM COLGATE TOTAL MINT CREME DENTAL 30G + ENXAGUANTE BUCAL 60ML + ESCOVA DENTAL | G31: Kit Viagem Colgate Estojo + Creme Dental Original Mint 30g + Enxaguante Bucal Clean Mint 60ml + Escova Dental Macia Colgate Total 1 Unidade | H31: Kit Viagem Colgate Escova Dental + Creme Dental 30gr + Enxaguante Bucal 60ml | I31: Kit Colgate Estojo Creme Dental 30g + Enxaguante Bucal 60ml + Escova Dental
A32: 7891010601188 | B32: Condicionador Infantil Johnson's Gotas de Brilho com 200ml | C32: Condicionador Infantil Johnson&#x27 s Baby Gotas de Brilho 200ml | D32: Condicionador Johnsons Kids Gotas de Brilho 200ml | E32: Condicionador Infantil Johnson&#39 s Gotas De Brilho Com 200ml | F32: CONDICIONADOR JOHNSONS KIDS GOTAS DE BRILHO 200ML | G32: Condicionador Infantil Johnson & Johnson Baby - 200ml Gotas de Brilho
A33: 7896018750968 | B33: Shampoo Huggies Kids Nutrição e Força Hulk 360ml | C33: Shampoo Huggies Kids Nutrição e Força Hulk 360ml | D33: Shampoo Huggies Kids Nutrição e Força Hulk 360ml | E33: Shampoo Huggies Kids Nutrição E Força Hulk 360ml | F33: SHAMPOO INFANTIL HUGGIES KIDS NUTRIÇÃO E FORÇA HULK 360ML | G33: Shampoo Infantil Huggies Kids Hulk Nutrição e Força 360ml | H33: Shampoo Huggies Kids Hulk Nutrição E Força 360ml | I33: Shampoo Huggies Kids Hulk Nutrição e Força Hulk 360ml
A34: 7891150094741 | B34: Desodorante Antitranspirante Creme Dove Creme Sérum Reparação Diária Feminino 48h 50g | C34: Desodorante Dove Creme Sérum Reparação Diária 50g | D34: Desodorante Antitranspirante Creme Dove Reparação Diária 50g | E34: Desodorante Antitranspirante Creme Dove Creme Sérum Feminino 48h Vitamina E Hidratante 50g | F34: DESODORANTE EM CREME SÉRUM DOVE REPARAÇÃO DIÁRIA 50G | G34: Desodorante Antitranspirante Dove Reparação Diária 48h Creme Sérum 50g | H34: Desodorante Dove Feminino 50gr Creme Serum Bisnaga Reparacao Diaria | I34: Desodorante Dove Creme Sérum Reparação Diária 50g
A35: 7891150049871 | B35: Creme Dental Closeup Triple Menta Americana 70g | C35: Creme Dental Close Up Tripla Proteção Menta Americana 70 g | D35: Creme Dental Close Up Triple M Americana 70g | E35: Creme Dental Closeup Tripla Proteção Menta Americana 70g | F35: CREME DENTAL COM FLÚOR CLOSEUP TRIPLE MENTA AMERICANA 70G | G35: Creme Dental Closeup Tripla Proteção Sabor Menta Americana 70g | H35: Creme Dental Closeup Triple Menta Americana 70g | I35: Creme Dental com flúor Closeup Triple Menta Americana 70g
A36: 7891150049895 | B36: Creme Dental Closeup Triple Menta 70g | C36: Creme Dental Close Up Triple Menta 70g | D36: Creme Dental Close Up Triple Menta 70g | E36: Creme Dental Closeup Tripla Proteção Menta 70g | F36: CREME DENTAL CLOSEUP TRIPLE MENTA 70G | G36: Creme Dental Closeup Tripla Proteção Sabor Menta 70g | H36: Creme Dental Closeup Triple Menta 70g | I36: Creme Dental Closeup Triple Menta 70g
A37: 7891150095267 | B37: Clear Shampoo Men Anticaspa Ice Cool Menthol 200ml | H37: Shampoo Clear Men Leve 200 Pague 170ml Ice Cool Menth Especial
A38: 7896006216483 | B38: Xantinon Racemetionina 100mg + Colina 20mg 30 comprimidos | C38: Xantinon Racemetionina 100mg + Colina 20mg 30 Comprimidos | D38: Xantinon 100mg + 20mg 30 Comprimidos Revestidos União Química | E38: Xantinon Racemetionina 100mg + Colina 20mg 30 Comprimidos | F38: XANTINON 30 COMPRIMIDOS | G38: Xantinon 100mg + 20mg 30 Comprimidos Revestidos | H38: Xantinon Com 30 Comprimidos Revestidos | I38: Hepatoprotetor Xantinon 100mg + 20mg 30 Comprimidos Revestidos
A39: 7896006201977 | B39: Triquilar Levonorgestrel 0,05mg + Etinilestradiol 0,03mg 21 drágeas | C39: Triquilar 21 Drágeas | F39: TRIQUILAR LEVONORGESTREL 0,05MG + ETINILESTRADIOL 0,03MG 21 DRÁGEAS | G39: Triquilar 21 Drágeas | H39: Triquilar Com 21 Comprimidos Revestidos | I39: Triquilar Etinilestradiol 0,03mg + Levonorgestrel 0,125mg 21 Drágeas
A40: 7896006222620 | B40: Octifen Fumarato de Cetotifeno 0,25mg/ml Solução Oftálmica 5ml | C40: Octifen 0,25mg Colírio Com 5ml | D40: Octifen Colírio 0,25mg/ml 5ml Genom | E40: Octifen Fumarato De Cetotifeno 0,25mg/Ml Solução Oftálmica 5ml | F40: OCTIFEN FUMARATO DE CETOTIFENO 0,25MG/ML COLÍRIO 5ML | G40: Octifen 0,25mg/ml Solução Oftálmica 5ml | H40: Octifen 0,25mg Colírio 5ml | I40: Colírio Octifen Fumarato De Cetotifeno 0,25mg/ml 5ml
...
